Workbook

Sheet README
A1: Greyborn — Tuning Spreadsheet
A2: Live source for every number in spec/01–05. Starting values for playtesting.
A4: Legend
A5: Blue text = input value. Edit these.
A6: Black text = formula. Don't overwrite; it recalculates.
A7: Green text = formula pulling from another sheet.
A8: Yellow fill = key lever (see Spec 05 §12, balance levers).
A10: Sheets
A11: Stats by level — L1 / L10 / L20 anchors per lineage (inputs) and every level in between (formulas). Spec 01.
A12: EXP & Respawn — EXP curve, cumulative EXP, respawn timer, Tenacity. Spec 05 §2, §9.
A13: Abilities — every Q/E/R and basic attack, with damage at L10 and L20 Power. Spec 02.
A14: Ultimates — all 42 Ultimate Forms with damage at L20 Power. Spec 03.
... A21: Where the GDD and this file disagree, the GDD's decisions win and both spec and sheet are corrected.

Sheet Stats by level
A1: Stats by level (Spec 01) — S-curve between anchors
A2: Growth: S(t) = 0.5·t + 0.5·(3t² − 2t³), piecewise L1→L10 and L10→L20, so L10 lands exactly on its anchor. Level numbers are in row 4.
A3: Key | B3: Lineage | C3: Stat | D3: L1 anchor | E3: L10 anchor | F3: L20 anchor | G3: L1 | H3: L2 | I3: L3 | J3: L4 | K3: L5 | L3: L6 | M3: L7 | N3: L8 | O3: L9 | P3: L10 | Q3: L11 | R3: L12 | S3: L13 | T3: L14 | U3: L15 | V3: L16 | W3: L17 | X3: L18 | Y3: L19 | Z3: L20
C4: Level → | G4: 1 | H4: 2 | I4: 3 | J4: 4 | K4: 5 | L4: 6 | M4: 7 | N4: 8 | O4: 9 | P4: 10 | Q4: 11 | R4: 12 | S4: 13 | T4: 14 | U4: 15 | V4: 16 | W4: 17 | X4: 18 | Y4: 19 | Z4: 20
A5: Titan|Health | B5: Titan | C5: Health | D5: 600 | E5: 2600 | F5: 5200 | G5: =ROUND(IF(G$4<=10,$D5+($E5-$D5)*(0.5*((G$4-1)/9)+0.5*(3*((G$4-1)/9)^2-2*((G$4-1)/9)^3)),$E5+($F5-$E5)*(0.5*((G$4-10)/10)+0.5*(3*((G$4-10)/10)^2-2*((G$4-10)/10)^3))),0) -> 600 | H5: =ROUND(IF(H$4<=10,$D5+($E5-$D5)*(0.5*((H$4-1)/9)+0.5*(3*((H$4-1)/9)^2-2*((H$4-1)/9)^3)),$E5+($F5-$E5)*(0.5*((H$4-10)/10)+0.5*(3*((H$4-10)/10)^2-2*((H$4-10)/10)^3))),0) -> 745 | I5: =ROUND(IF(I$4<=10,$D5+($E5-$D5)*(0.5*((I$4-1)/9)+0.5*(3*((I$4-1)/9)^2-2*((I$4-1)/9)^3)),$E5+($F5-$E5)*(0.5*((I$4-10)/10)+0.5*(3*((I$4-10)/10)^2-2*((I$4-10)/10)^3))),0) -> 948 | J5: =ROUND(IF(J$4<=10,$D5+($E5-$D5)*(0.5*((J$4-1)/9)+0.5*(3*((J$4-1)/9)^2-2*((J$4-1)/9)^3)),$E5+($F5-$E5)*(0.5*((J$4-10)/10)+0.5*(3*((J$4-10)/10)^2-2*((J$4-10)/10)^3))),0) -> 1193 | K5: =ROUND(IF(K$4<=10,$D5+($E5-$D5)*(0.5*((K$4-1)/9)+0.5*(3*((K$4-1)/9)^2-2*((K$4-1)/9)^3)),$E5+($F5-$E5)*(0.5*((K$4-10)/10)+0.5*(3*((K$4-10)/10)^2-2*((K$4-10)/10)^3))),0) -> 1461 | L5: =ROUND(IF(L$4<=10,$D5+($E5-$D5)*(0.5*((L$4-1)/9)+0.5*(3*((L$4-1)/9)^2-2*((L$4-1)/9)^3)),$E5+($F5-$E5)*(0.5*((L$4-10)/10)+0.5*(3*((L$4-10)/10)^2-2*((L$4-10)/10)^3))),0) -> 1739 | M5: =ROUND(IF(M$4<=10,$D5+($E5-$D5)*(0.5*((M$4-1)/9)+0.5*(3*((M$4-1)/9)^2-2*((M$4-1)/9)^3)),$E5+($F5-$E5)*(0.5*((M$4-10)/10)+0.5*(3*((M$4-10)/10)^2-2*((M$4-10)/10)^3))),0) -> 2007 | N5: =ROUND(IF(N$4<=10,$D5+($E5-$D5)*(0.5*((N$4-1)/9)+0.5*(3*((N$4-1)/9)^2-2*((N$4-1)/9)^3)),$E5+($F5-$E5)*(0.5*((N$4-10)/10)+0.5*(3*((N$4-10)/10)^2-2*((N$4-10)/10)^3))),0) -> 2252 | ... Z5: =ROUND(IF(Z$4<=10,$D5+($E5-$D5)*(0.5*((Z$4-1)/9)+0.5*(3*((Z$4-1)/9)^2-2*((Z$4-1)/9)^3)),$E5+($F5-$E5)*(0.5*((Z$4-10)/10)+0.5*(3*((Z$4-10)/10)^2-2*((Z$4-10)/10)^3))),0) -> 5200
A6: Titan|Power | B6: Titan | C6: Power | D6: 40 | E6: 100 | F6: 180 | G6: =ROUND(IF(G$4<=10,$D6+($E6-$D6)*(0.5*((G$4-1)/9)+0.5*(3*((G$4-1)/9)^2-2*((G$4-1)/9)^3)),$E6+($F6-$E6)*(0.5*((G$4-10)/10)+0.5*(3*((G$4-10)/10)^2-2*((G$4-10)/10)^3))),0) -> 40 | H6: =ROUND(IF(H$4<=10,$D6+($E6-$D6)*(0.5*((H$4-1)/9)+0.5*(3*((H$4-1)/9)^2-2*((H$4-1)/9)^3)),$E6+($F6-$E6)*(0.5*((H$4-10)/10)+0.5*(3*((H$4-10)/10)^2-2*((H$4-10)/10)^3))),0) -> 44 | I6: =ROUND(IF(I$4<=10,$D6+($E6-$D6)*(0.5*((I$4-1)/9)+0.5*(3*((I$4-1)/9)^2-2*((I$4-1)/9)^3)),$E6+($F6-$E6)*(0.5*((I$4-10)/10)+0.5*(3*((I$4-10)/10)^2-2*((I$4-10)/10)^3))),0) -> 50 | J6: =ROUND(IF(J$4<=10,$D6+($E6-$D6)*(0.5*((J$4-1)/9)+0.5*(3*((J$4-1)/9)^2-2*((J$4-1)/9)^3)),$E6+($F6-$E6)*(0.5*((J$4-10)/10)+0.5*(3*((J$4-10)/10)^2-2*((J$4-10)/10)^3))),0) -> 58 | K6: =ROUND(IF(K$4<=10,$D6+($E6-$D6)*(0.5*((K$4-1)/9)+0.5*(3*((K$4-1)/9)^2-2*((K$4-1)/9)^3)),$E6+($F6-$E6)*(0.5*((K$4-10)/10)+0.5*(3*((K$4-10)/10)^2-2*((K$4-10)/10)^3))),0) -> 66 | L6: =ROUND(IF(L$4<=10,$D6+($E6-$D6)*(0.5*((L$4-1)/9)+0.5*(3*((L$4-1)/9)^2-2*((L$4-1)/9)^3)),$E6+($F6-$E6)*(0.5*((L$4-10)/10)+0.5*(3*((L$4-10)/10)^2-2*((L$4-10)/10)^3))),0) -> 74 | M6: =ROUND(IF(M$4<=10,$D6+($E6-$D6)*(0.5*((M$4-1)/9)+0.5*(3*((M$4-1)/9)^2-2*((M$4-1)/9)^3)),$E6+($F6-$E6)*(0.5*((M$4-10)/10)+0.5*(3*((M$4-10)/10)^2-2*((M$4-10)/10)^3))),0) -> 82 | N6: =ROUND(IF(N$4<=10,$D6+($E6-$D6)*(0.5*((N$4-1)/9)+0.5*(3*((N$4-1)/9)^2-2*((N$4-1)/9)^3)),$E6+($F6-$E6)*(0.5*((N$4-10)/10)+0.5*(3*((N$4-10)/10)^2-2*((N$4-10)/10)^3))),0) -> 90 | ... Z6: =ROUND(IF(Z$4<=10,$D6+($E6-$D6)*(0.5*((Z$4-1)/9)+0.5*(3*((Z$4-1)/9)^2-2*((Z$4-1)/9)^3)),$E6+($F6-$E6)*(0.5*((Z$4-10)/10)+0.5*(3*((Z$4-10)/10)^2-2*((Z$4-10)/10)^3))),0) -> 180
A7: Titan|Speed % | B7: Titan | C7: Speed % | D7: 100 | E7: 90 | F7: 85 | G7: =ROUND(IF(G$4<=10,$D7+($E7-$D7)*(0.5*((G$4-1)/9)+0.5*(3*((G$4-1)/9)^2-2*((G$4-1)/9)^3)),$E7+($F7-$E7)*(0.5*((G$4-10)/10)+0.5*(3*((G$4-10)/10)^2-2*((G$4-10)/10)^3))),0) -> 100 | H7: =ROUND(IF(H$4<=10,$D7+($E7-$D7)*(0.5*((H$4-1)/9)+0.5*(3*((H$4-1)/9)^2-2*((H$4-1)/9)^3)),$E7+($F7-$E7)*(0.5*((H$4-10)/10)+0.5*(3*((H$4-10)/10)^2-2*((H$4-10)/10)^3))),0) -> 99 | I7: =ROUND(IF(I$4<=10,$D7+($E7-$D7)*(0.5*((I$4-1)/9)+0.5*(3*((I$4-1)/9)^2-2*((I$4-1)/9)^3)),$E7+($F7-$E7)*(0.5*((I$4-10)/10)+0.5*(3*((I$4-10)/10)^2-2*((I$4-10)/10)^3))),0) -> 98 | J7: =ROUND(IF(J$4<=10,$D7+($E7-$D7)*(0.5*((J$4-1)/9)+0.5*(3*((J$4-1)/9)^2-2*((J$4-1)/9)^3)),$E7+($F7-$E7)*(0.5*((J$4-10)/10)+0.5*(3*((J$4-10)/10)^2-2*((J$4-10)/10)^3))),0) -> 97 | K7: =ROUND(IF(K$4<=10,$D7+($E7-$D7)*(0.5*((K$4-1)/9)+0.5*(3*((K$4-1)/9)^2-2*((K$4-1)/9)^3)),$E7+($F7-$E7)*(0.5*((K$4-10)/10)+0.5*(3*((K$4-10)/10)^2-2*((K$4-10)/10)^3))),0) -> 96 | L7: =ROUND(IF(L$4<=10,$D7+($E7-$D7)*(0.5*((L$4-1)/9)+0.5*(3*((L$4-1)/9)^2-2*((L$4-1)/9)^3)),$E7+($F7-$E7)*(0.5*((L$4-10)/10)+0.5*(3*((L$4-10)/10)^2-2*((L$4-10)/10)^3))),0) -> 94 | M7: =ROUND(IF(M$4<=10,$D7+($E7-$D7)*(0.5*((M$4-1)/9)+0.5*(3*((M$4-1)/9)^2-2*((M$4-1)/9)^3)),$E7+($F7-$E7)*(0.5*((M$4-10)/10)+0.5*(3*((M$4-10)/10)^2-2*((M$4-10)/10)^3))),0) -> 93 | N7: =ROUND(IF(N$4<=10,$D7+($E7-$D7)*(0.5*((N$4-1)/9)+0.5*(3*((N$4-1)/9)^2-2*((N$4-1)/9)^3)),$E7+($F7-$E7)*(0.5*((N$4-10)/10)+0.5*(3*((N$4-10)/10)^2-2*((N$4-10)/10)^3))),0) -> 92 | ... Z7: =ROUND(IF(Z$4<=10,$D7+($E7-$D7)*(0.5*((Z$4-1)/9)+0.5*(3*((Z$4-1)/9)^2-2*((Z$4-1)/9)^3)),$E7+($F7-$E7)*(0.5*((Z$4-10)/10)+0.5*(3*((Z$4-10)/10)^2-2*((Z$4-10)/10)^3))),0) -> 85
A8: Titan|Control | B8: Titan | C8: Control | D8: 10 | E8: 40 | F8: 70 | G8: =ROUND(IF(G$4<=10,$D8+($E8-$D8)*(0.5*((G$4-1)/9)+0.5*(3*((G$4-1)/9)^2-2*((G$4-1)/9)^3)),$E8+($F8-$E8)*(0.5*((G$4-10)/10)+0.5*(3*((G$4-10)/10)^2-2*((G$4-10)/10)^3))),0) -> 10 | H8: =ROUND(IF(H$4<=10,$D8+($E8-$D8)*(0.5*((H$4-1)/9)+0.5*(3*((H$4-1)/9)^2-2*((H$4-1)/9)^3)),$E8+($F8-$E8)*(0.5*((H$4-10)/10)+0.5*(3*((H$4-10)/10)^2-2*((H$4-10)/10)^3))),0) -> 12 | I8: =ROUND(IF(I$4<=10,$D8+($E8-$D8)*(0.5*((I$4-1)/9)+0.5*(3*((I$4-1)/9)^2-2*((I$4-1)/9)^3)),$E8+($F8-$E8)*(0.5*((I$4-10)/10)+0.5*(3*((I$4-10)/10)^2-2*((I$4-10)/10)^3))),0) -> 15 | J8: =ROUND(IF(J$4<=10,$D8+($E8-$D8)*(0.5*((J$4-1)/9)+0.5*(3*((J$4-1)/9)^2-2*((J$4-1)/9)^3)),$E8+($F8-$E8)*(0.5*((J$4-10)/10)+0.5*(3*((J$4-10)/10)^2-2*((J$4-10)/10)^3))),0) -> 19 | K8: =ROUND(IF(K$4<=10,$D8+($E8-$D8)*(0.5*((K$4-1)/9)+0.5*(3*((K$4-1)/9)^2-2*((K$4-1)/9)^3)),$E8+($F8-$E8)*(0.5*((K$4-10)/10)+0.5*(3*((K$4-10)/10)^2-2*((K$4-10)/10)^3))),0) -> 23 | L8: =ROUND(IF(L$4<=10,$D8+($E8-$D8)*(0.5*((L$4-1)/9)+0.5*(3*((L$4-1)/9)^2-2*((L$4-1)/9)^3)),$E8+($F8-$E8)*(0.5*((L$4-10)/10)+0.5*(3*((L$4-10)/10)^2-2*((L$4-10)/10)^3))),0) -> 27 | M8: =ROUND(IF(M$4<=10,$D8+($E8-$D8)*(0.5*((M$4-1)/9)+0.5*(3*((M$4-1)/9)^2-2*((M$4-1)/9)^3)),$E8+($F8-$E8)*(0.5*((M$4-10)/10)+0.5*(3*((M$4-10)/10)^2-2*((M$4-10)/10)^3))),0) -> 31 | N8: =ROUND(IF(N$4<=10,$D8+($E8-$D8)*(0.5*((N$4-1)/9)+0.5*(3*((N$4-1)/9)^2-2*((N$4-1)/9)^3)),$E8+($F8-$E8)*(0.5*((N$4-10)/10)+0.5*(3*((N$4-10)/10)^2-2*((N$4-10)/10)^3))),0) -> 35 | ... Z8: =ROUND(IF(Z$4<=10,$D8+($E8-$D8)*(0.5*((Z$4-1)/9)+0.5*(3*((Z$4-1)/9)^2-2*((Z$4-1)/9)^3)),$E8+($F8-$E8)*(0.5*((Z$4-10)/10)+0.5*(3*((Z$4-10)/10)^2-2*((Z$4-10)/10)^3))),0) -> 70
A9: Brawler|Health | B9: Brawler | C9: Health | D9: 600 | E9: 2000 | F9: 3800 | G9: =ROUND(IF(G$4<=10,$D9+($E9-$D9)*(0.5*((G$4-1)/9)+0.5*(3*((G$4-1)/9)^2-2*((G$4-1)/9)^3)),$E9+($F9-$E9)*(0.5*((G$4-10)/10)+0.5*(3*((G$4-10)/10)^2-2*((G$4-10)/10)^3))),0) -> 600 | H9: =ROUND(IF(H$4<=10,$D9+($E9-$D9)*(0.5*((H$4-1)/9)+0.5*(3*((H$4-1)/9)^2-2*((H$4-1)/9)^3)),$E9+($F9-$E9)*(0.5*((H$4-10)/10)+0.5*(3*((H$4-10)/10)^2-2*((H$4-10)/10)^3))),0) -> 702 | I9: =ROUND(IF(I$4<=10,$D9+($E9-$D9)*(0.5*((I$4-1)/9)+0.5*(3*((I$4-1)/9)^2-2*((I$4-1)/9)^3)),$E9+($F9-$E9)*(0.5*((I$4-10)/10)+0.5*(3*((I$4-10)/10)^2-2*((I$4-10)/10)^3))),0) -> 844 | J9: =ROUND(IF(J$4<=10,$D9+($E9-$D9)*(0.5*((J$4-1)/9)+0.5*(3*((J$4-1)/9)^2-2*((J$4-1)/9)^3)),$E9+($F9-$E9)*(0.5*((J$4-10)/10)+0.5*(3*((J$4-10)/10)^2-2*((J$4-10)/10)^3))),0) -> 1015 | K9: =ROUND(IF(K$4<=10,$D9+($E9-$D9)*(0.5*((K$4-1)/9)+0.5*(3*((K$4-1)/9)^2-2*((K$4-1)/9)^3)),$E9+($F9-$E9)*(0.5*((K$4-10)/10)+0.5*(3*((K$4-10)/10)^2-2*((K$4-10)/10)^3))),0) -> 1203 | L9: =ROUND(IF(L$4<=10,$D9+($E9-$D9)*(0.5*((L$4-1)/9)+0.5*(3*((L$4-1)/9)^2-2*((L$4-1)/9)^3)),$E9+($F9-$E9)*(0.5*((L$4-10)/10)+0.5*(3*((L$4-10)/10)^2-2*((L$4-10)/10)^3))),0) -> 1397 | M9: =ROUND(IF(M$4<=10,$D9+($E9-$D9)*(0.5*((M$4-1)/9)+0.5*(3*((M$4-1)/9)^2-2*((M$4-1)/9)^3)),$E9+($F9-$E9)*(0.5*((M$4-10)/10)+0.5*(3*((M$4-10)/10)^2-2*((M$4-10)/10)^3))),0) -> 1585 | N9: =ROUND(IF(N$4<=10,$D9+($E9-$D9)*(0.5*((N$4-1)/9)+0.5*(3*((N$4-1)/9)^2-2*((N$4-1)/9)^3)),$E9+($F9-$E9)*(0.5*((N$4-10)/10)+0.5*(3*((N$4-10)/10)^2-2*((N$4-10)/10)^3))),0) -> 1756 | ... Z9: =ROUND(IF(Z$4<=10,$D9+($E9-$D9)*(0.5*((Z$4-1)/9)+0.5*(3*((Z$4-1)/9)^2-2*((Z$4-1)/9)^3)),$E9+($F9-$E9)*(0.5*((Z$4-10)/10)+0.5*(3*((Z$4-10)/10)^2-2*((Z$4-10)/10)^3))),0) -> 3800
A10: Brawler|Power | B10: Brawler | C10: Power | D10: 40 | E10: 130 | F10: 240 | G10: =ROUND(IF(G$4<=10,$D10+($E10-$D10)*(0.5*((G$4-1)/9)+0.5*(3*((G$4-1)/9)^2-2*((G$4-1)/9)^3)),$E10+($F10-$E10)*(0.5*((G$4-10)/10)+0.5*(3*((G$4-10)/10)^2-2*((G$4-10)/10)^3))),0) -> 40 | H10: =ROUND(IF(H$4<=10,$D10+($E10-$D10)*(0.5*((H$4-1)/9)+0.5*(3*((H$4-1)/9)^2-2*((H$4-1)/9)^3)),$E10+($F10-$E10)*(0.5*((H$4-10)/10)+0.5*(3*((H$4-10)/10)^2-2*((H$4-10)/10)^3))),0) -> 47 | I10: =ROUND(IF(I$4<=10,$D10+($E10-$D10)*(0.5*((I$4-1)/9)+0.5*(3*((I$4-1)/9)^2-2*((I$4-1)/9)^3)),$E10+($F10-$E10)*(0.5*((I$4-10)/10)+0.5*(3*((I$4-10)/10)^2-2*((I$4-10)/10)^3))),0) -> 56 | J10: =ROUND(IF(J$4<=10,$D10+($E10-$D10)*(0.5*((J$4-1)/9)+0.5*(3*((J$4-1)/9)^2-2*((J$4-1)/9)^3)),$E10+($F10-$E10)*(0.5*((J$4-10)/10)+0.5*(3*((J$4-10)/10)^2-2*((J$4-10)/10)^3))),0) -> 67 | K10: =ROUND(IF(K$4<=10,$D10+($E10-$D10)*(0.5*((K$4-1)/9)+0.5*(3*((K$4-1)/9)^2-2*((K$4-1)/9)^3)),$E10+($F10-$E10)*(0.5*((K$4-10)/10)+0.5*(3*((K$4-10)/10)^2-2*((K$4-10)/10)^3))),0) -> 79 | L10: =ROUND(IF(L$4<=10,$D10+($E10-$D10)*(0.5*((L$4-1)/9)+0.5*(3*((L$4-1)/9)^2-2*((L$4-1)/9)^3)),$E10+($F10-$E10)*(0.5*((L$4-10)/10)+0.5*(3*((L$4-10)/10)^2-2*((L$4-10)/10)^3))),0) -> 91 | M10: =ROUND(IF(M$4<=10,$D10+($E10-$D10)*(0.5*((M$4-1)/9)+0.5*(3*((M$4-1)/9)^2-2*((M$4-1)/9)^3)),$E10+($F10-$E10)*(0.5*((M$4-10)/10)+0.5*(3*((M$4-10)/10)^2-2*((M$4-10)/10)^3))),0) -> 103 | N10: =ROUND(IF(N$4<=10,$D10+($E10-$D10)*(0.5*((N$4-1)/9)+0.5*(3*((N$4-1)/9)^2-2*((N$4-1)/9)^3)),$E10+($F10-$E10)*(0.5*((N$4-10)/10)+0.5*(3*((N$4-10)/10)^2-2*((N$4-10)/10)^3))),0) -> 114 | ... Z10: =ROUND(IF(Z$4<=10,$D10+($E10-$D10)*(0.5*((Z$4-1)/9)+0.5*(3*((Z$4-1)/9)^2-2*((Z$4-1)/9)^3)),$E10+($F10-$E10)*(0.5*((Z$4-10)/10)+0.5*(3*((Z$4-10)/10)^2-2*((Z$4-10)/10)^3))),0) -> 240
A11: Brawler|Speed % | B11: Brawler | C11: Speed % | D11: 100 | E11: 105 | F11: 110 | G11: =ROUND(IF(G$4<=10,$D11+($E11-$D11)*(0.5*((G$4-1)/9)+0.5*(3*((G$4-1)/9)^2-2*((G$4-1)/9)^3)),$E11+($F11-$E11)*(0.5*((G$4-10)/10)+0.5*(3*((G$4-10)/10)^2-2*((G$4-10)/10)^3))),0) -> 100 | H11: =ROUND(IF(H$4<=10,$D11+($E11-$D11)*(0.5*((H$4-1)/9)+0.5*(3*((H$4-1)/9)^2-2*((H$4-1)/9)^3)),$E11+($F11-$E11)*(0.5*((H$4-10)/10)+0.5*(3*((H$4-10)/10)^2-2*((H$4-10)/10)^3))),0) -> 100 | I11: =ROUND(IF(I$4<=10,$D11+($E11-$D11)*(0.5*((I$4-1)/9)+0.5*(3*((I$4-1)/9)^2-2*((I$4-1)/9)^3)),$E11+($F11-$E11)*(0.5*((I$4-10)/10)+0.5*(3*((I$4-10)/10)^2-2*((I$4-10)/10)^3))),0) -> 101 | J11: =ROUND(IF(J$4<=10,$D11+($E11-$D11)*(0.5*((J$4-1)/9)+0.5*(3*((J$4-1)/9)^2-2*((J$4-1)/9)^3)),$E11+($F11-$E11)*(0.5*((J$4-10)/10)+0.5*(3*((J$4-10)/10)^2-2*((J$4-10)/10)^3))),0) -> 101 | K11: =ROUND(IF(K$4<=10,$D11+($E11-$D11)*(0.5*((K$4-1)/9)+0.5*(3*((K$4-1)/9)^2-2*((K$4-1)/9)^3)),$E11+($F11-$E11)*(0.5*((K$4-10)/10)+0.5*(3*((K$4-10)/10)^2-2*((K$4-10)/10)^3))),0) -> 102 | L11: =ROUND(IF(L$4<=10,$D11+($E11-$D11)*(0.5*((L$4-1)/9)+0.5*(3*((L$4-1)/9)^2-2*((L$4-1)/9)^3)),$E11+($F11-$E11)*(0.5*((L$4-10)/10)+0.5*(3*((L$4-10)/10)^2-2*((L$4-10)/10)^3))),0) -> 103 | M11: =ROUND(IF(M$4<=10,$D11+($E11-$D11)*(0.5*((M$4-1)/9)+0.5*(3*((M$4-1)/9)^2-2*((M$4-1)/9)^3)),$E11+($F11-$E11)*(0.5*((M$4-10)/10)+0.5*(3*((M$4-10)/10)^2-2*((M$4-10)/10)^3))),0) -> 104 | N11: =ROUND(IF(N$4<=10,$D11+($E11-$D11)*(0.5*((N$4-1)/9)+0.5*(3*((N$4-1)/9)^2-2*((N$4-1)/9)^3)),$E11+($F11-$E11)*(0.5*((N$4-10)/10)+0.5*(3*((N$4-10)/10)^2-2*((N$4-10)/10)^3))),0) -> 104 | ... Z11: =ROUND(IF(Z$4<=10,$D11+($E11-$D11)*(0.5*((Z$4-1)/9)+0.5*(3*((Z$4-1)/9)^2-2*((Z$4-1)/9)^3)),$E11+($F11-$E11)*(0.5*((Z$4-10)/10)+0.5*(3*((Z$4-10)/10)^2-2*((Z$4-10)/10)^3))),0) -> 110
A12: Brawler|Control | B12: Brawler | C12: Control | D12: 10 | E12: 30 | F12: 50 | G12: =ROUND(IF(G$4<=10,$D12+($E12-$D12)*(0.5*((G$4-1)/9)+0.5*(3*((G$4-1)/9)^2-2*((G$4-1)/9)^3)),$E12+($F12-$E12)*(0.5*((G$4-10)/10)+0.5*(3*((G$4-10)/10)^2-2*((G$4-10)/10)^3))),0) -> 10 | H12: =ROUND(IF(H$4<=10,$D12+($E12-$D12)*(0.5*((H$4-1)/9)+0.5*(3*((H$4-1)/9)^2-2*((H$4-1)/9)^3)),$E12+($F12-$E12)*(0.5*((H$4-10)/10)+0.5*(3*((H$4-10)/10)^2-2*((H$4-10)/10)^3))),0) -> 11 | I12: =ROUND(IF(I$4<=10,$D12+($E12-$D12)*(0.5*((I$4-1)/9)+0.5*(3*((I$4-1)/9)^2-2*((I$4-1)/9)^3)),$E12+($F12-$E12)*(0.5*((I$4-10)/10)+0.5*(3*((I$4-10)/10)^2-2*((I$4-10)/10)^3))),0) -> 13 | J12: =ROUND(IF(J$4<=10,$D12+($E12-$D12)*(0.5*((J$4-1)/9)+0.5*(3*((J$4-1)/9)^2-2*((J$4-1)/9)^3)),$E12+($F12-$E12)*(0.5*((J$4-10)/10)+0.5*(3*((J$4-10)/10)^2-2*((J$4-10)/10)^3))),0) -> 16 | K12: =ROUND(IF(K$4<=10,$D12+($E12-$D12)*(0.5*((K$4-1)/9)+0.5*(3*((K$4-1)/9)^2-2*((K$4-1)/9)^3)),$E12+($F12-$E12)*(0.5*((K$4-10)/10)+0.5*(3*((K$4-10)/10)^2-2*((K$4-10)/10)^3))),0) -> 19 | L12: =ROUND(IF(L$4<=10,$D12+($E12-$D12)*(0.5*((L$4-1)/9)+0.5*(3*((L$4-1)/9)^2-2*((L$4-1)/9)^3)),$E12+($F12-$E12)*(0.5*((L$4-10)/10)+0.5*(3*((L$4-10)/10)^2-2*((L$4-10)/10)^3))),0) -> 21 | M12: =ROUND(IF(M$4<=10,$D12+($E12-$D12)*(0.5*((M$4-1)/9)+0.5*(3*((M$4-1)/9)^2-2*((M$4-1)/9)^3)),$E12+($F12-$E12)*(0.5*((M$4-10)/10)+0.5*(3*((M$4-10)/10)^2-2*((M$4-10)/10)^3))),0) -> 24 | N12: =ROUND(IF(N$4<=10,$D12+($E12-$D12)*(0.5*((N$4-1)/9)+0.5*(3*((N$4-1)/9)^2-2*((N$4-1)/9)^3)),$E12+($F12-$E12)*(0.5*((N$4-10)/10)+0.5*(3*((N$4-10)/10)^2-2*((N$4-10)/10)^3))),0) -> 27 | ... Z12: =ROUND(IF(Z$4<=10,$D12+($E12-$D12)*(0.5*((Z$4-1)/9)+0.5*(3*((Z$4-1)/9)^2-2*((Z$4-1)/9)^3)),$E12+($F12-$E12)*(0.5*((Z$4-10)/10)+0.5*(3*((Z$4-10)/10)^2-2*((Z$4-10)/10)^3))),0) -> 50
A13: Verdant|Health | B13: Verdant | C13: Health | D13: 600 | E13: 1800 | F13: 3400 | G13: =ROUND(IF(G$4<=10,$D13+($E13-$D13)*(0.5*((G$4-1)/9)+0.5*(3*((G$4-1)/9)^2-2*((G$4-1)/9)^3)),$E13+($F13-$E13)*(0.5*((G$4-10)/10)+0.5*(3*((G$4-10)/10)^2-2*((G$4-10)/10)^3))),0) -> 600 | H13: =ROUND(IF(H$4<=10,$D13+($E13-$D13)*(0.5*((H$4-1)/9)+0.5*(3*((H$4-1)/9)^2-2*((H$4-1)/9)^3)),$E13+($F13-$E13)*(0.5*((H$4-10)/10)+0.5*(3*((H$4-10)/10)^2-2*((H$4-10)/10)^3))),0) -> 687 | I13: =ROUND(IF(I$4<=10,$D13+($E13-$D13)*(0.5*((I$4-1)/9)+0.5*(3*((I$4-1)/9)^2-2*((I$4-1)/9)^3)),$E13+($F13-$E13)*(0.5*((I$4-10)/10)+0.5*(3*((I$4-10)/10)^2-2*((I$4-10)/10)^3))),0) -> 809 | J13: =ROUND(IF(J$4<=10,$D13+($E13-$D13)*(0.5*((J$4-1)/9)+0.5*(3*((J$4-1)/9)^2-2*((J$4-1)/9)^3)),$E13+($F13-$E13)*(0.5*((J$4-10)/10)+0.5*(3*((J$4-10)/10)^2-2*((J$4-10)/10)^3))),0) -> 956 | K13: =ROUND(IF(K$4<=10,$D13+($E13-$D13)*(0.5*((K$4-1)/9)+0.5*(3*((K$4-1)/9)^2-2*((K$4-1)/9)^3)),$E13+($F13-$E13)*(0.5*((K$4-10)/10)+0.5*(3*((K$4-10)/10)^2-2*((K$4-10)/10)^3))),0) -> 1117 | L13: =ROUND(IF(L$4<=10,$D13+($E13-$D13)*(0.5*((L$4-1)/9)+0.5*(3*((L$4-1)/9)^2-2*((L$4-1)/9)^3)),$E13+($F13-$E13)*(0.5*((L$4-10)/10)+0.5*(3*((L$4-10)/10)^2-2*((L$4-10)/10)^3))),0) -> 1283 | M13: =ROUND(IF(M$4<=10,$D13+($E13-$D13)*(0.5*((M$4-1)/9)+0.5*(3*((M$4-1)/9)^2-2*((M$4-1)/9)^3)),$E13+($F13-$E13)*(0.5*((M$4-10)/10)+0.5*(3*((M$4-10)/10)^2-2*((M$4-10)/10)^3))),0) -> 1444 | N13: =ROUND(IF(N$4<=10,$D13+($E13-$D13)*(0.5*((N$4-1)/9)+0.5*(3*((N$4-1)/9)^2-2*((N$4-1)/9)^3)),$E13+($F13-$E13)*(0.5*((N$4-10)/10)+0.5*(3*((N$4-10)/10)^2-2*((N$4-10)/10)^3))),0) -> 1591 | ... Z13: =ROUND(IF(Z$4<=10,$D13+($E13-$D13)*(0.5*((Z$4-1)/9)+0.5*(3*((Z$4-1)/9)^2-2*((Z$4-1)/9)^3)),$E13+($F13-$E13)*(0.5*((Z$4-10)/10)+0.5*(3*((Z$4-10)/10)^2-2*((Z$4-10)/10)^3))),0) -> 3400
A14: Verdant|Power | B14: Verdant | C14: Power | D14: 40 | E14: 85 | F14: 150 | G14: =ROUND(IF(G$4<=10,$D14+($E14-$D14)*(0.5*((G$4-1)/9)+0.5*(3*((G$4-1)/9)^2-2*((G$4-1)/9)^3)),$E14+($F14-$E14)*(0.5*((G$4-10)/10)+0.5*(3*((G$4-10)/10)^2-2*((G$4-10)/10)^3))),0) -> 40 | H14: =ROUND(IF(H$4<=10,$D14+($E14-$D14)*(0.5*((H$4-1)/9)+0.5*(3*((H$4-1)/9)^2-2*((H$4-1)/9)^3)),$E14+($F14-$E14)*(0.5*((H$4-10)/10)+0.5*(3*((H$4-10)/10)^2-2*((H$4-10)/10)^3))),0) -> 43 | I14: =ROUND(IF(I$4<=10,$D14+($E14-$D14)*(0.5*((I$4-1)/9)+0.5*(3*((I$4-1)/9)^2-2*((I$4-1)/9)^3)),$E14+($F14-$E14)*(0.5*((I$4-10)/10)+0.5*(3*((I$4-10)/10)^2-2*((I$4-10)/10)^3))),0) -> 48 | J14: =ROUND(IF(J$4<=10,$D14+($E14-$D14)*(0.5*((J$4-1)/9)+0.5*(3*((J$4-1)/9)^2-2*((J$4-1)/9)^3)),$E14+($F14-$E14)*(0.5*((J$4-10)/10)+0.5*(3*((J$4-10)/10)^2-2*((J$4-10)/10)^3))),0) -> 53 | K14: =ROUND(IF(K$4<=10,$D14+($E14-$D14)*(0.5*((K$4-1)/9)+0.5*(3*((K$4-1)/9)^2-2*((K$4-1)/9)^3)),$E14+($F14-$E14)*(0.5*((K$4-10)/10)+0.5*(3*((K$4-10)/10)^2-2*((K$4-10)/10)^3))),0) -> 59 | L14: =ROUND(IF(L$4<=10,$D14+($E14-$D14)*(0.5*((L$4-1)/9)+0.5*(3*((L$4-1)/9)^2-2*((L$4-1)/9)^3)),$E14+($F14-$E14)*(0.5*((L$4-10)/10)+0.5*(3*((L$4-10)/10)^2-2*((L$4-10)/10)^3))),0) -> 66 | M14: =ROUND(IF(M$4<=10,$D14+($E14-$D14)*(0.5*((M$4-1)/9)+0.5*(3*((M$4-1)/9)^2-2*((M$4-1)/9)^3)),$E14+($F14-$E14)*(0.5*((M$4-10)/10)+0.5*(3*((M$4-10)/10)^2-2*((M$4-10)/10)^3))),0) -> 72 | N14: =ROUND(IF(N$4<=10,$D14+($E14-$D14)*(0.5*((N$4-1)/9)+0.5*(3*((N$4-1)/9)^2-2*((N$4-1)/9)^3)),$E14+($F14-$E14)*(0.5*((N$4-10)/10)+0.5*(3*((N$4-10)/10)^2-2*((N$4-10)/10)^3))),0) -> 77 | ... Z14: =ROUND(IF(Z$4<=10,$D14+($E14-$D14)*(0.5*((Z$4-1)/9)+0.5*(3*((Z$4-1)/9)^2-2*((Z$4-1)/9)^3)),$E14+($F14-$E14)*(0.5*((Z$4-10)/10)+0.5*(3*((Z$4-10)/10)^2-2*((Z$4-10)/10)^3))),0) -> 150
A15: Verdant|Speed % | B15: Verdant | C15: Speed % | D15: 100 | E15: 95 | F15: 95 | G15: =ROUND(IF(G$4<=10,$D15+($E15-$D15)*(0.5*((G$4-1)/9)+0.5*(3*((G$4-1)/9)^2-2*((G$4-1)/9)^3)),$E15+($F15-$E15)*(0.5*((G$4-10)/10)+0.5*(3*((G$4-10)/10)^2-2*((G$4-10)/10)^3))),0) -> 100 | H15: =ROUND(IF(H$4<=10,$D15+($E15-$D15)*(0.5*((H$4-1)/9)+0.5*(3*((H$4-1)/9)^2-2*((H$4-1)/9)^3)),$E15+($F15-$E15)*(0.5*((H$4-10)/10)+0.5*(3*((H$4-10)/10)^2-2*((H$4-10)/10)^3))),0) -> 100 | I15: =ROUND(IF(I$4<=10,$D15+($E15-$D15)*(0.5*((I$4-1)/9)+0.5*(3*((I$4-1)/9)^2-2*((I$4-1)/9)^3)),$E15+($F15-$E15)*(0.5*((I$4-10)/10)+0.5*(3*((I$4-10)/10)^2-2*((I$4-10)/10)^3))),0) -> 99 | J15: =ROUND(IF(J$4<=10,$D15+($E15-$D15)*(0.5*((J$4-1)/9)+0.5*(3*((J$4-1)/9)^2-2*((J$4-1)/9)^3)),$E15+($F15-$E15)*(0.5*((J$4-10)/10)+0.5*(3*((J$4-10)/10)^2-2*((J$4-10)/10)^3))),0) -> 99 | K15: =ROUND(IF(K$4<=10,$D15+($E15-$D15)*(0.5*((K$4-1)/9)+0.5*(3*((K$4-1)/9)^2-2*((K$4-1)/9)^3)),$E15+($F15-$E15)*(0.5*((K$4-10)/10)+0.5*(3*((K$4-10)/10)^2-2*((K$4-10)/10)^3))),0) -> 98 | L15: =ROUND(IF(L$4<=10,$D15+($E15-$D15)*(0.5*((L$4-1)/9)+0.5*(3*((L$4-1)/9)^2-2*((L$4-1)/9)^3)),$E15+($F15-$E15)*(0.5*((L$4-10)/10)+0.5*(3*((L$4-10)/10)^2-2*((L$4-10)/10)^3))),0) -> 97 | M15: =ROUND(IF(M$4<=10,$D15+($E15-$D15)*(0.5*((M$4-1)/9)+0.5*(3*((M$4-1)/9)^2-2*((M$4-1)/9)^3)),$E15+($F15-$E15)*(0.5*((M$4-10)/10)+0.5*(3*((M$4-10)/10)^2-2*((M$4-10)/10)^3))),0) -> 96 | N15: =ROUND(IF(N$4<=10,$D15+($E15-$D15)*(0.5*((N$4-1)/9)+0.5*(3*((N$4-1)/9)^2-2*((N$4-1)/9)^3)),$E15+($F15-$E15)*(0.5*((N$4-10)/10)+0.5*(3*((N$4-10)/10)^2-2*((N$4-10)/10)^3))),0) -> 96 | ... Z15: =ROUND(IF(Z$4<=10,$D15+($E15-$D15)*(0.5*((Z$4-1)/9)+0.5*(3*((Z$4-1)/9)^2-2*((Z$4-1)/9)^3)),$E15+($F15-$E15)*(0.5*((Z$4-10)/10)+0.5*(3*((Z$4-10)/10)^2-2*((Z$4-10)/10)^3))),0) -> 95
A16: Verdant|Control | B16: Verdant | C16: Control | D16: 10 | E16: 60 | F16: 110 | G16: =ROUND(IF(G$4<=10,$D16+($E16-$D16)*(0.5*((G$4-1)/9)+0.5*(3*((G$4-1)/9)^2-2*((G$4-1)/9)^3)),$E16+($F16-$E16)*(0.5*((G$4-10)/10)+0.5*(3*((G$4-10)/10)^2-2*((G$4-10)/10)^3))),0) -> 10 | H16: =ROUND(IF(H$4<=10,$D16+($E16-$D16)*(0.5*((H$4-1)/9)+0.5*(3*((H$4-1)/9)^2-2*((H$4-1)/9)^3)),$E16+($F16-$E16)*(0.5*((H$4-10)/10)+0.5*(3*((H$4-10)/10)^2-2*((H$4-10)/10)^3))),0) -> 14 | I16: =ROUND(IF(I$4<=10,$D16+($E16-$D16)*(0.5*((I$4-1)/9)+0.5*(3*((I$4-1)/9)^2-2*((I$4-1)/9)^3)),$E16+($F16-$E16)*(0.5*((I$4-10)/10)+0.5*(3*((I$4-10)/10)^2-2*((I$4-10)/10)^3))),0) -> 19 | J16: =ROUND(IF(J$4<=10,$D16+($E16-$D16)*(0.5*((J$4-1)/9)+0.5*(3*((J$4-1)/9)^2-2*((J$4-1)/9)^3)),$E16+($F16-$E16)*(0.5*((J$4-10)/10)+0.5*(3*((J$4-10)/10)^2-2*((J$4-10)/10)^3))),0) -> 25 | K16: =ROUND(IF(K$4<=10,$D16+($E16-$D16)*(0.5*((K$4-1)/9)+0.5*(3*((K$4-1)/9)^2-2*((K$4-1)/9)^3)),$E16+($F16-$E16)*(0.5*((K$4-10)/10)+0.5*(3*((K$4-10)/10)^2-2*((K$4-10)/10)^3))),0) -> 32 | L16: =ROUND(IF(L$4<=10,$D16+($E16-$D16)*(0.5*((L$4-1)/9)+0.5*(3*((L$4-1)/9)^2-2*((L$4-1)/9)^3)),$E16+($F16-$E16)*(0.5*((L$4-10)/10)+0.5*(3*((L$4-10)/10)^2-2*((L$4-10)/10)^3))),0) -> 38 | M16: =ROUND(IF(M$4<=10,$D16+($E16-$D16)*(0.5*((M$4-1)/9)+0.5*(3*((M$4-1)/9)^2-2*((M$4-1)/9)^3)),$E16+($F16-$E16)*(0.5*((M$4-10)/10)+0.5*(3*((M$4-10)/10)^2-2*((M$4-10)/10)^3))),0) -> 45 | N16: =ROUND(IF(N$4<=10,$D16+($E16-$D16)*(0.5*((N$4-1)/9)+0.5*(3*((N$4-1)/9)^2-2*((N$4-1)/9)^3)),$E16+($F16-$E16)*(0.5*((N$4-10)/10)+0.5*(3*((N$4-10)/10)^2-2*((N$4-10)/10)^3))),0) -> 51 | ... Z16: =ROUND(IF(Z$4<=10,$D16+($E16-$D16)*(0.5*((Z$4-1)/9)+0.5*(3*((Z$4-1)/9)^2-2*((Z$4-1)/9)^3)),$E16+($F16-$E16)*(0.5*((Z$4-10)/10)+0.5*(3*((Z$4-10)/10)^2-2*((Z$4-10)/10)^3))),0) -> 110
... A32: Stillheart|Control | B32: Stillheart | C32: Control | D32: 10 | E32: 55 | F32: 100 | G32: =ROUND(IF(G$4<=10,$D32+($E32-$D32)*(0.5*((G$4-1)/9)+0.5*(3*((G$4-1)/9)^2-2*((G$4-1)/9)^3)),$E32+($F32-$E32)*(0.5*((G$4-10)/10)+0.5*(3*((G$4-10)/10)^2-2*((G$4-10)/10)^3))),0) -> 10 | H32: =ROUND(IF(H$4<=10,$D32+($E32-$D32)*(0.5*((H$4-1)/9)+0.5*(3*((H$4-1)/9)^2-2*((H$4-1)/9)^3)),$E32+($F32-$E32)*(0.5*((H$4-10)/10)+0.5*(3*((H$4-10)/10)^2-2*((H$4-10)/10)^3))),0) -> 13 | I32: =ROUND(IF(I$4<=10,$D32+($E32-$D32)*(0.5*((I$4-1)/9)+0.5*(3*((I$4-1)/9)^2-2*((I$4-1)/9)^3)),$E32+($F32-$E32)*(0.5*((I$4-10)/10)+0.5*(3*((I$4-10)/10)^2-2*((I$4-10)/10)^3))),0) -> 18 | J32: =ROUND(IF(J$4<=10,$D32+($E32-$D32)*(0.5*((J$4-1)/9)+0.5*(3*((J$4-1)/9)^2-2*((J$4-1)/9)^3)),$E32+($F32-$E32)*(0.5*((J$4-10)/10)+0.5*(3*((J$4-10)/10)^2-2*((J$4-10)/10)^3))),0) -> 23 | K32: =ROUND(IF(K$4<=10,$D32+($E32-$D32)*(0.5*((K$4-1)/9)+0.5*(3*((K$4-1)/9)^2-2*((K$4-1)/9)^3)),$E32+($F32-$E32)*(0.5*((K$4-10)/10)+0.5*(3*((K$4-10)/10)^2-2*((K$4-10)/10)^3))),0) -> 29 | L32: =ROUND(IF(L$4<=10,$D32+($E32-$D32)*(0.5*((L$4-1)/9)+0.5*(3*((L$4-1)/9)^2-2*((L$4-1)/9)^3)),$E32+($F32-$E32)*(0.5*((L$4-10)/10)+0.5*(3*((L$4-10)/10)^2-2*((L$4-10)/10)^3))),0) -> 36 | M32: =ROUND(IF(M$4<=10,$D32+($E32-$D32)*(0.5*((M$4-1)/9)+0.5*(3*((M$4-1)/9)^2-2*((M$4-1)/9)^3)),$E32+($F32-$E32)*(0.5*((M$4-10)/10)+0.5*(3*((M$4-10)/10)^2-2*((M$4-10)/10)^3))),0) -> 42 | N32: =ROUND(IF(N$4<=10,$D32+($E32-$D32)*(0.5*((N$4-1)/9)+0.5*(3*((N$4-1)/9)^2-2*((N$4-1)/9)^3)),$E32+($F32-$E32)*(0.5*((N$4-10)/10)+0.5*(3*((N$4-10)/10)^2-2*((N$4-10)/10)^3))),0) -> 47 | ... Z32: =ROUND(IF(Z$4<=10,$D32+($E32-$D32)*(0.5*((Z$4-1)/9)+0.5*(3*((Z$4-1)/9)^2-2*((Z$4-1)/9)^3)),$E32+($F32-$E32)*(0.5*((Z$4-10)/10)+0.5*(3*((Z$4-10)/10)^2-2*((Z$4-10)/10)^3))),0) -> 100

Sheet EXP & Respawn
A1: EXP curve, respawn and Tenacity (Spec 05 §2, §9; Spec 01)
J2: Inputs
A3: Level | B3: EXP to next | C3: Cumulative EXP to reach | D3: Respawn (Phases 1–3) s | E3: Respawn (Phase 4) s | F3: Tenacity | G3: Dominance shares | H3: Bounty on death (cores)
J4: EXP base | K4: 60
A5: 1 | B5: =IF(A5<20,$K$4+$K$5*A5,"—") -> 75 | C5: =0 -> 0 | D5: =$K$6+$K$7*A5 -> 6 | E5: =D5+$K$8 -> 11 | F5: =MIN($K$10,$K$9*(A5-1)) -> 0 | G5: =MAX(0,A5-15) -> 0 | H5: =$K$11+$K$12*A5 -> 115 | J5: EXP per level | K5: 15
A6: 2 | B6: =IF(A6<20,$K$4+$K$5*A6,"—") -> 90 | C6: =C5+B5 -> 75 | D6: =$K$6+$K$7*A6 -> 7 | E6: =D6+$K$8 -> 12 | F6: =MIN($K$10,$K$9*(A6-1)) -> 0.02 | G6: =MAX(0,A6-15) -> 0 | H6: =$K$11+$K$12*A6 -> 130 | J6: Respawn base (s) | K6: 5
A7: 3 | B7: =IF(A7<20,$K$4+$K$5*A7,"—") -> 105 | C7: =C6+B6 -> 165 | D7: =$K$6+$K$7*A7 -> 8 | E7: =D7+$K$8 -> 13 | F7: =MIN($K$10,$K$9*(A7-1)) -> 0.04 | G7: =MAX(0,A7-15) -> 0 | H7: =$K$11+$K$12*A7 -> 145 | J7: Respawn per level (s) | K7: 1
A8: 4 | B8: =IF(A8<20,$K$4+$K$5*A8,"—") -> 120 | C8: =C7+B7 -> 270 | D8: =$K$6+$K$7*A8 -> 9 | E8: =D8+$K$8 -> 14 | F8: =MIN($K$10,$K$9*(A8-1)) -> 0.06 | G8: =MAX(0,A8-15) -> 0 | H8: =$K$11+$K$12*A8 -> 160 | J8: Phase 4 respawn extra (s) | K8: 5
A9: 5 | B9: =IF(A9<20,$K$4+$K$5*A9,"—") -> 135 | C9: =C8+B8 -> 390 | D9: =$K$6+$K$7*A9 -> 10 | E9: =D9+$K$8 -> 15 | F9: =MIN($K$10,$K$9*(A9-1)) -> 0.08 | G9: =MAX(0,A9-15) -> 0 | H9: =$K$11+$K$12*A9 -> 175 | J9: Tenacity per level (L2–L15) | K9: 0.02
A10: 6 | B10: =IF(A10<20,$K$4+$K$5*A10,"—") -> 150 | C10: =C9+B9 -> 525 | D10: =$K$6+$K$7*A10 -> 11 | E10: =D10+$K$8 -> 16 | F10: =MIN($K$10,$K$9*(A10-1)) -> 0.1 | G10: =MAX(0,A10-15) -> 0 | H10: =$K$11+$K$12*A10 -> 190 | J10: Tenacity cap | K10: 0.28
A11: 7 | B11: =IF(A11<20,$K$4+$K$5*A11,"—") -> 165 | C11: =C10+B10 -> 675 | D11: =$K$6+$K$7*A11 -> 12 | E11: =D11+$K$8 -> 17 | F11: =MIN($K$10,$K$9*(A11-1)) -> 0.12 | G11: =MAX(0,A11-15) -> 0 | H11: =$K$11+$K$12*A11 -> 205 | J11: Bounty base | K11: 100
A12: 8 | B12: =IF(A12<20,$K$4+$K$5*A12,"—") -> 180 | C12: =C11+B11 -> 840 | D12: =$K$6+$K$7*A12 -> 13 | E12: =D12+$K$8 -> 18 | F12: =MIN($K$10,$K$9*(A12-1)) -> 0.14 | G12: =MAX(0,A12-15) -> 0 | H12: =$K$11+$K$12*A12 -> 220 | J12: Bounty per level | K12: 15
A13: 9 | B13: =IF(A13<20,$K$4+$K$5*A13,"—") -> 195 | C13: =C12+B12 -> 1020 | D13: =$K$6+$K$7*A13 -> 14 | E13: =D13+$K$8 -> 19 | F13: =MIN($K$10,$K$9*(A13-1)) -> 0.16 | G13: =MAX(0,A13-15) -> 0 | H13: =$K$11+$K$12*A13 -> 235
A14: 10 | B14: =IF(A14<20,$K$4+$K$5*A14,"—") -> 210 | C14: =C13+B13 -> 1215 | D14: =$K$6+$K$7*A14 -> 15 | E14: =D14+$K$8 -> 20 | F14: =MIN($K$10,$K$9*(A14-1)) -> 0.18 | G14: =MAX(0,A14-15) -> 0 | H14: =$K$11+$K$12*A14 -> 250
A15: 11 | B15: =IF(A15<20,$K$4+$K$5*A15,"—") -> 225 | C15: =C14+B14 -> 1425 | D15: =$K$6+$K$7*A15 -> 16 | E15: =D15+$K$8 -> 21 | F15: =MIN($K$10,$K$9*(A15-1)) -> 0.2 | G15: =MAX(0,A15-15) -> 0 | H15: =$K$11+$K$12*A15 -> 265
A16: 12 | B16: =IF(A16<20,$K$4+$K$5*A16,"—") -> 240 | C16: =C15+B15 -> 1650 | D16: =$K$6+$K$7*A16 -> 17 | E16: =D16+$K$8 -> 22 | F16: =MIN($K$10,$K$9*(A16-1)) -> 0.22 | G16: =MAX(0,A16-15) -> 0 | H16: =$K$11+$K$12*A16 -> 280
A17: 13 | B17: =IF(A17<20,$K$4+$K$5*A17,"—") -> 255 | C17: =C16+B16 -> 1890 | D17: =$K$6+$K$7*A17 -> 18 | E17: =D17+$K$8 -> 23 | F17: =MIN($K$10,$K$9*(A17-1)) -> 0.24 | G17: =MAX(0,A17-15) -> 0 | H17: =$K$11+$K$12*A17 -> 295
A18: 14 | B18: =IF(A18<20,$K$4+$K$5*A18,"—") -> 270 | C18: =C17+B17 -> 2145 | D18: =$K$6+$K$7*A18 -> 19 | E18: =D18+$K$8 -> 24 | F18: =MIN($K$10,$K$9*(A18-1)) -> 0.26 | G18: =MAX(0,A18-15) -> 0 | H18: =$K$11+$K$12*A18 -> 310
A19: 15 | B19: =IF(A19<20,$K$4+$K$5*A19,"—") -> 285 | C19: =C18+B18 -> 2415 | D19: =$K$6+$K$7*A19 -> 20 | E19: =D19+$K$8 -> 25 | F19: =MIN($K$10,$K$9*(A19-1)) -> 0.28 | G19: =MAX(0,A19-15) -> 0 | H19: =$K$11+$K$12*A19 -> 325
A20: 16 | B20: =IF(A20<20,$K$4+$K$5*A20,"—") -> 300 | C20: =C19+B19 -> 2700 | D20: =$K$6+$K$7*A20 -> 21 | E20: =D20+$K$8 -> 26 | F20: =MIN($K$10,$K$9*(A20-1)) -> 0.28 | G20: =MAX(0,A20-15) -> 1 | H20: =$K$11+$K$12*A20 -> 340
A21: 17 | B21: =IF(A21<20,$K$4+$K$5*A21,"—") -> 315 | C21: =C20+B20 -> 3000 | D21: =$K$6+$K$7*A21 -> 22 | E21: =D21+$K$8 -> 27 | F21: =MIN($K$10,$K$9*(A21-1)) -> 0.28 | G21: =MAX(0,A21-15) -> 2 | H21: =$K$11+$K$12*A21 -> 355
A22: 18 | B22: =IF(A22<20,$K$4+$K$5*A22,"—") -> 330 | C22: =C21+B21 -> 3315 | D22: =$K$6+$K$7*A22 -> 23 | E22: =D22+$K$8 -> 28 | F22: =MIN($K$10,$K$9*(A22-1)) -> 0.28 | G22: =MAX(0,A22-15) -> 3 | H22: =$K$11+$K$12*A22 -> 370
A23: 19 | B23: =IF(A23<20,$K$4+$K$5*A23,"—") -> 345 | C23: =C22+B22 -> 3645 | D23: =$K$6+$K$7*A23 -> 24 | E23: =D23+$K$8 -> 29 | F23: =MIN($K$10,$K$9*(A23-1)) -> 0.28 | G23: =MAX(0,A23-15) -> 4 | H23: =$K$11+$K$12*A23 -> 385
A24: 20 | B24: =IF(A24<20,$K$4+$K$5*A24,"—") -> — | C24: =C23+B23 -> 3990 | D24: =$K$6+$K$7*A24 -> 25 | E24: =D24+$K$8 -> 30 | F24: =MIN($K$10,$K$9*(A24-1)) -> 0.28 | G24: =MAX(0,A24-15) -> 5 | H24: =$K$11+$K$12*A24 -> 400
A26: Check: total EXP to L20 (Spec 05 says 5,320) | C26: =C24 -> 3990

Sheet Abilities
A1: Lineage abilities (Spec 02) — damage computed from Stats by level
A3: Lineage | B3: Slot | C3: Ability | D3: Range / area | E3: Timing | F3: Effect | G3: Damage (text) | H3: Base | I3: Ratio × P | J3: Cooldown (s) | K3: Damage @ L10 | L3: Damage @ L20
A4: Titan | B4: Basic | C4: fist slam | D4: melee, 3 m (scales) | E4: 0.8 hits/s | G4: fist slam · melee, 3 m (scales) · 0.8 hits/s · 1.2 × P. | H4: 0 | I4: 1.2 | K4: =IF(I4="","",ROUND(H4+I4*INDEX('Stats by level'!$G$5:$Z$32,MATCH($A4&"|Power",'Stats by level'!$A$5:$A$32,0),10),0)) -> 120 | L4: =IF(I4="","",ROUND(H4+I4*INDEX('Stats by level'!$G$5:$Z$32,MATCH($A4&"|Power",'Stats by level'!$A$5:$A$32,0),20),0)) -> 216
A5: Titan | B5: Q | C5: Quake Slam | D5: Circle, radius 5 m (scales), centred on self | E5: 0.5 s wind-up with a visible ring | F5: Stagger 0.8 s; triggers Smash & Roll | G5: 60 + 0.8 × P | H5: 60 | I5: 0.8 | J5: 12 | K5: =IF(I5="","",ROUND(H5+I5*INDEX('Stats by level'!$G$5:$Z$32,MATCH($A5&"|Power",'Stats by level'!$A$5:$A$32,0),10),0)) -> 140 | L5: =IF(I5="","",ROUND(H5+I5*INDEX('Stats by level'!$G$5:$Z$32,MATCH($A5&"|Power",'Stats by level'!$A$5:$A$32,0),20),0)) -> 204
A6: Titan | B6: E | C6: Bulwark | D6: Frontal 120° cone | E6: Instant; lasts 3 s | F6: −60% damage from the front; Titan slowed 30% | G6: — | J6: 16 | K6: =IF(I6="","",ROUND(H6+I6*INDEX('Stats by level'!$G$5:$Z$32,MATCH($A6&"|Power",'Stats by level'!$A$5:$A$32,0),10),0)) | L6: =IF(I6="","",ROUND(H6+I6*INDEX('Stats by level'!$G$5:$Z$32,MATCH($A6&"|Power",'Stats by level'!$A$5:$A$32,0),20),0))
A7: Titan | B7: R | C7: Rampart Charge | D7: Line, 12 m (scales) | E7: 0.3 s wind-up; 1.0 s charge | F7: Unstoppable; carries up to 2 enemies to the end | G7: 80 + 1.0 × P | H7: 80 | I7: 1 | J7: 18 | K7: =IF(I7="","",ROUND(H7+I7*INDEX('Stats by level'!$G$5:$Z$32,MATCH($A7&"|Power",'Stats by level'!$A$5:$A$32,0),10),0)) -> 180 | L7: =IF(I7="","",ROUND(H7+I7*INDEX('Stats by level'!$G$5:$Z$32,MATCH($A7&"|Power",'Stats by level'!$A$5:$A$32,0),20),0)) -> 260
A8: Brawler | B8: Basic | C8: fist combo | D8: melee, 2.5 m (scales) | E8: 1.4 hits/s | G8: fist combo · melee, 2.5 m (scales) · 1.4 hits/s · 1.0 × P. | H8: 0 | I8: 1 | K8: =IF(I8="","",ROUND(H8+I8*INDEX('Stats by level'!$G$5:$Z$32,MATCH($A8&"|Power",'Stats by level'!$A$5:$A$32,0),10),0)) -> 130 | L8: =IF(I8="","",ROUND(H8+I8*INDEX('Stats by level'!$G$5:$Z$32,MATCH($A8&"|Power",'Stats by level'!$A$5:$A$32,0),20),0)) -> 240
A9: Brawler | B9: Q | C9: Roll Commit | D9: Line, 8 m (scales) | E9: 0.6 s roll | F9: Unstoppable; ends in an uppercut that staggers 0.5 s. Chest weak point exposed for 1.0 s after | G9: 70 + 1.0 × P (uppercut) | H9: 70 | I9: 1 | J9: 10 | K9: =IF(I9="","",ROUND(H9+I9*INDEX('Stats by level'!$G$5:$Z$32,MATCH($A9&"|Power",'Stats by level'!$A$5:$A$32,0),10),0)) -> 200 | L9: =IF(I9="","",ROUND(H9+I9*INDEX('Stats by level'!$G$5:$Z$32,MATCH($A9&"|Power",'Stats by level'!$A$5:$A$32,0),20),0)) -> 310
A10: Brawler | B10: E | C10: Haymaker | D10: Melee, 3 m | E10: Charge 0.3–1.5 s | F10: Damage scales with charge; full charge knocks back 6 m | G10: 50 + 0.6 × P (min) to 120 + 1.4 × P (full) | H10: 50 | I10: 0.6 | J10: 9 | K10: =IF(I10="","",ROUND(H10+I10*INDEX('Stats by level'!$G$5:$Z$32,MATCH($A10&"|Power",'Stats by level'!$A$5:$A$32,0),10),0)) -> 128 | L10: =IF(I10="","",ROUND(H10+I10*INDEX('Stats by level'!$G$5:$Z$32,MATCH($A10&"|Power",'Stats by level'!$A$5:$A$32,0),20),0)) -> 194
A11: Brawler | B11: R | C11: Grapple | D11: Melee, 3 m | E11: 0.6 s hold, then throw | F11: Grabs a lower-Stage target, throws it 8 m in the aimed direction | G11: 40 + 0.5 × P, +40 on landing | H11: 40 | I11: 0.5 | J11: 16 | K11: =IF(I11="","",ROUND(H11+I11*INDEX('Stats by level'!$G$5:$Z$32,MATCH($A11&"|Power",'Stats by level'!$A$5:$A$32,0),10),0)) -> 105 | L11: =IF(I11="","",ROUND(H11+I11*INDEX('Stats by level'!$G$5:$Z$32,MATCH($A11&"|Power",'Stats by level'!$A$5:$A$32,0),20),0)) -> 160
A12: Verdant | B12: Basic | C12: antler sweep | D12: melee, 3 m (scales) | E12: 1.0 hits/s | G12: antler sweep · melee, 3 m (scales) · 1.0 hits/s · 0.9 × P. | H12: 0 | I12: 0.9 | K12: =IF(I12="","",ROUND(H12+I12*INDEX('Stats by level'!$G$5:$Z$32,MATCH($A12&"|Power",'Stats by level'!$A$5:$A$32,0),10),0)) -> 77 | L12: =IF(I12="","",ROUND(H12+I12*INDEX('Stats by level'!$G$5:$Z$32,MATCH($A12&"|Power",'Stats by level'!$A$5:$A$32,0),20),0)) -> 135
A13: Verdant | B13: Q | C13: Bramble Wall | D13: Wall, 10 m long (scales), 1.5 m tall, placed up to 15 m away | E13: 0.4 s to grow; lasts 6 s | F13: Blocks movement and projectiles; can be destroyed | G13: Wall Health 400 + 2 × P | H13: 400 | I13: 2 | J13: 18 | K13: =IF(I13="","",ROUND(H13+I13*INDEX('Stats by level'!$G$5:$Z$32,MATCH($A13&"|Power",'Stats by level'!$A$5:$A$32,0),10),0)) -> 570 | L13: =IF(I13="","",ROUND(H13+I13*INDEX('Stats by level'!$G$5:$Z$32,MATCH($A13&"|Power",'Stats by level'!$A$5:$A$32,0),20),0)) -> 700
A14: Verdant | B14: E | C14: Sap Draw | D14: Ally or self within 15 m | E14: Heal over 4 s | F14: Heals the target; costs 40 team SAP | G14: Heal 120 + 1.0 × P | H14: 120 | I14: 1 | J14: 16 | K14: =IF(I14="","",ROUND(H14+I14*INDEX('Stats by level'!$G$5:$Z$32,MATCH($A14&"|Power",'Stats by level'!$A$5:$A$32,0),10),0)) -> 205 | L14: =IF(I14="","",ROUND(H14+I14*INDEX('Stats by level'!$G$5:$Z$32,MATCH($A14&"|Power",'Stats by level'!$A$5:$A$32,0),20),0)) -> 270
A15: Verdant | B15: R | C15: Entangle | D15: Circle, radius 3 m (scales), up to 15 m away | E15: 0.6 s delay | F15: Root 1.2 s | G15: 30 + 0.4 × P | H15: 30 | I15: 0.4 | J15: 14 | K15: =IF(I15="","",ROUND(H15+I15*INDEX('Stats by level'!$G$5:$Z$32,MATCH($A15&"|Power",'Stats by level'!$A$5:$A$32,0),10),0)) -> 64 | L15: =IF(I15="","",ROUND(H15+I15*INDEX('Stats by level'!$G$5:$Z$32,MATCH($A15&"|Power",'Stats by level'!$A$5:$A$32,0),20),0)) -> 90
A16: Hollow | B16: Basic | C16: void bolt | D16: ranged, 15 m | E16: 1.0 shots/s | G16: void bolt · ranged, 15 m · 1.0 shots/s · 0.8 × P · projectile speed 30 m/s. | H16: 0 | I16: 0.8 | K16: =IF(I16="","",ROUND(H16+I16*INDEX('Stats by level'!$G$5:$Z$32,MATCH($A16&"|Power",'Stats by level'!$A$5:$A$32,0),10),0)) -> 92 | L16: =IF(I16="","",ROUND(H16+I16*INDEX('Stats by level'!$G$5:$Z$32,MATCH($A16&"|Power",'Stats by level'!$A$5:$A$32,0),20),0)) -> 168
A17: Hollow | B17: Q | C17: Void Rift | D17: Circle, radius 4 m (scales), up to 18 m away | E17: 0.3 s to open; lasts 4 s | F17: Enemies inside: slowed 30%, Control −40%; triggers Void Garden on rooted ground | G17: — | J17: 14 | K17: =IF(I17="","",ROUND(H17+I17*INDEX('Stats by level'!$G$5:$Z$32,MATCH($A17&"|Power",'Stats by level'!$A$5:$A$32,0),10),0)) | L17: =IF(I17="","",ROUND(H17+I17*INDEX('Stats by level'!$G$5:$Z$32,MATCH($A17&"|Power",'Stats by level'!$A$5:$A$32,0),20),0))
A18: Hollow | B18: E | C18: Hollow Step | D18: Blink, 8 m (scales) | E18: 0.1 s | F18: Teleport; passes through units and Bramble Walls, not terrain | G18: — | J18: 12 | K18: =IF(I18="","",ROUND(H18+I18*INDEX('Stats by level'!$G$5:$Z$32,MATCH($A18&"|Power",'Stats by level'!$A$5:$A$32,0),10),0)) | L18: =IF(I18="","",ROUND(H18+I18*INDEX('Stats by level'!$G$5:$Z$32,MATCH($A18&"|Power",'Stats by level'!$A$5:$A$32,0),20),0))
A19: Hollow | B19: R | C19: Null Pulse | D19: Circle, radius 6 m (scales) around self | E19: 0.3 s wind-up | F19: Silence 1.5 s | G19: 40 + 0.5 × P | H19: 40 | I19: 0.5 | J19: 20 | K19: =IF(I19="","",ROUND(H19+I19*INDEX('Stats by level'!$G$5:$Z$32,MATCH($A19&"|Power",'Stats by level'!$A$5:$A$32,0),10),0)) -> 98 | L19: =IF(I19="","",ROUND(H19+I19*INDEX('Stats by level'!$G$5:$Z$32,MATCH($A19&"|Power",'Stats by level'!$A$5:$A$32,0),20),0)) -> 145
A20: Thornrunner | B20: Basic | C20: claw rake | D20: melee, 2.5 m (scales) | E20: 1.6 hits/s | G20: claw rake · melee, 2.5 m (scales) · 1.6 hits/s · 0.8 × P. | H20: 0 | I20: 0.8 | K20: =IF(I20="","",ROUND(H20+I20*INDEX('Stats by level'!$G$5:$Z$32,MATCH($A20&"|Power",'Stats by level'!$A$5:$A$32,0),10),0)) -> 100 | L20: =IF(I20="","",ROUND(H20+I20*INDEX('Stats by level'!$G$5:$Z$32,MATCH($A20&"|Power",'Stats by level'!$A$5:$A$32,0),20),0)) -> 184
A21: Thornrunner | B21: Q | C21: Thorn Dash | D21: Line, 9 m (scales), passes through enemies | E21: 0.3 s | F21: Damages and applies bleed to every enemy passed | G21: 40 + 0.6 × P, then bleed 10 + 0.15 × P per second for 4 s | H21: 40 | I21: 0.6 | J21: 8 | K21: =IF(I21="","",ROUND(H21+I21*INDEX('Stats by level'!$G$5:$Z$32,MATCH($A21&"|Power",'Stats by level'!$A$5:$A$32,0),10),0)) -> 115 | L21: =IF(I21="","",ROUND(H21+I21*INDEX('Stats by level'!$G$5:$Z$32,MATCH($A21&"|Power",'Stats by level'!$A$5:$A$32,0),20),0)) -> 178
A22: Thornrunner | B22: E | C22: Mark Prey | D22: Target enemy within 25 m, line of sight | E22: Instant | F22: Reveals the target for 6 s and exposes its weak point from every angle to the whole team; triggers Co-Stalk | G22: — | J22: 16 | K22: =IF(I22="","",ROUND(H22+I22*INDEX('Stats by level'!$G$5:$Z$32,MATCH($A22&"|Power",'Stats by level'!$A$5:$A$32,0),10),0)) | L22: =IF(I22="","",ROUND(H22+I22*INDEX('Stats by level'!$G$5:$Z$32,MATCH($A22&"|Power",'Stats by level'!$A$5:$A$32,0),20),0))
A23: Thornrunner | B23: R | C23: Barb Volley | D23: Cone 60°, 8 m | E23: 0.2 s | F23: Fires 8 barbs; a close target can be hit by up to 5 | G23: 12 + 0.15 × P per barb | H23: 12 | I23: 0.15 | J23: 10 | K23: =IF(I23="","",ROUND(H23+I23*INDEX('Stats by level'!$G$5:$Z$32,MATCH($A23&"|Power",'Stats by level'!$A$5:$A$32,0),10),0)) -> 31 | L23: =IF(I23="","",ROUND(H23+I23*INDEX('Stats by level'!$G$5:$Z$32,MATCH($A23&"|Power",'Stats by level'!$A$5:$A$32,0),20),0)) -> 47
A24: Bonespire | B24: Basic | C24: bone shard | D24: ranged, 25 m | E24: 0.9 shots/s | G24: bone shard · ranged, 25 m · 0.9 shots/s · 1.1 × P · projectile speed 40 m/s. | H24: 0 | I24: 1.1 | K24: =IF(I24="","",ROUND(H24+I24*INDEX('Stats by level'!$G$5:$Z$32,MATCH($A24&"|Power",'Stats by level'!$A$5:$A$32,0),10),0)) -> 154 | L24: =IF(I24="","",ROUND(H24+I24*INDEX('Stats by level'!$G$5:$Z$32,MATCH($A24&"|Power",'Stats by level'!$A$5:$A$32,0),20),0)) -> 286
A25: Bonespire | B25: Q | C25: Spire Lance | D25: Skillshot, 40 m (Stage 2: 45 m; Stage 3: 50 m), width 0.6 m | E25: 0.6 s wind-up (a loud crack heard at 60 m); projectile 60 m/s | F25: Hits the first enemy. ×1.5 on a weak point; ×2.0 on an exposed (Marked) weak point; triggers Co-Stalk | G25: 90 + 1.2 × P | H25: 90 | I25: 1.2 | J25: 9 | K25: =IF(I25="","",ROUND(H25+I25*INDEX('Stats by level'!$G$5:$Z$32,MATCH($A25&"|Power",'Stats by level'!$A$5:$A$32,0),10),0)) -> 258 | L25: =IF(I25="","",ROUND(H25+I25*INDEX('Stats by level'!$G$5:$Z$32,MATCH($A25&"|Power",'Stats by level'!$A$5:$A$32,0),20),0)) -> 402
A26: Bonespire | B26: E | C26: Ossuary | D26: Fence, 8 m long (scales), placed up to 15 m away | E26: 0.3 s to rise; lasts 5 s | F26: Blocks movement (not projectiles); can be destroyed | G26: Fence Health 300 + 1.5 × P | H26: 300 | I26: 1.5 | J26: 16 | K26: =IF(I26="","",ROUND(H26+I26*INDEX('Stats by level'!$G$5:$Z$32,MATCH($A26&"|Power",'Stats by level'!$A$5:$A$32,0),10),0)) -> 510 | L26: =IF(I26="","",ROUND(H26+I26*INDEX('Stats by level'!$G$5:$Z$32,MATCH($A26&"|Power",'Stats by level'!$A$5:$A$32,0),20),0)) -> 690
A27: Bonespire | B27: R | C27: Calcify | D27: Projectile, 20 m | E27: 0.2 s | F27: Slows 25% for 3 s. A second hit within 3 s: slow 50%. A third: stun 1.0 s | G27: 25 + 0.3 × P | H27: 25 | I27: 0.3 | J27: 6 | K27: =IF(I27="","",ROUND(H27+I27*INDEX('Stats by level'!$G$5:$Z$32,MATCH($A27&"|Power",'Stats by level'!$A$5:$A$32,0),10),0)) -> 67 | L27: =IF(I27="","",ROUND(H27+I27*INDEX('Stats by level'!$G$5:$Z$32,MATCH($A27&"|Power",'Stats by level'!$A$5:$A$32,0),20),0)) -> 103
A28: Stillheart | B28: Basic | C28: frost swipe | D28: melee, 3 m (scales) | E28: 0.9 hits/s | G28: frost swipe · melee, 3 m (scales) · 0.9 hits/s · 0.9 × P · slows 10% for 1 s. | H28: 0 | I28: 0.9 | K28: =IF(I28="","",ROUND(H28+I28*INDEX('Stats by level'!$G$5:$Z$32,MATCH($A28&"|Power",'Stats by level'!$A$5:$A$32,0),10),0)) -> 77 | L28: =IF(I28="","",ROUND(H28+I28*INDEX('Stats by level'!$G$5:$Z$32,MATCH($A28&"|Power",'Stats by level'!$A$5:$A$32,0),20),0)) -> 135
A29: Stillheart | B29: Q | C29: Lull | D29: Cone 50°, 10 m (scales) | E29: 0.3 s | F29: Slow 40% for 2 s. A second Lull on the same target within 3 s: Drowse 1.0 s (broken by damage) | G29: 20 + 0.3 × P | H29: 20 | I29: 0.3 | J29: 7 | K29: =IF(I29="","",ROUND(H29+I29*INDEX('Stats by level'!$G$5:$Z$32,MATCH($A29&"|Power",'Stats by level'!$A$5:$A$32,0),10),0)) -> 46 | L29: =IF(I29="","",ROUND(H29+I29*INDEX('Stats by level'!$G$5:$Z$32,MATCH($A29&"|Power",'Stats by level'!$A$5:$A$32,0),20),0)) -> 65
A30: Stillheart | B30: E | C30: Hibernate | D30: Self or an ally within 12 m | E30: Instant; 2 s | F30: Ice stasis: invulnerable and untargetable, can't act. Carried cores are safe | G30: — | J30: 24 | K30: =IF(I30="","",ROUND(H30+I30*INDEX('Stats by level'!$G$5:$Z$32,MATCH($A30&"|Power",'Stats by level'!$A$5:$A$32,0),10),0)) | L30: =IF(I30="","",ROUND(H30+I30*INDEX('Stats by level'!$G$5:$Z$32,MATCH($A30&"|Power",'Stats by level'!$A$5:$A$32,0),20),0))
A31: Stillheart | B31: R | C31: Long Night | D31: Circle, radius 7 m (scales), up to 15 m away | E31: 0.5 s to form; lasts 5 s | F31: Enemy cooldowns tick 30% slower inside | G31: — | J31: 22 | K31: =IF(I31="","",ROUND(H31+I31*INDEX('Stats by level'!$G$5:$Z$32,MATCH($A31&"|Power",'Stats by level'!$A$5:$A$32,0),10),0)) | L31: =IF(I31="","",ROUND(H31+I31*INDEX('Stats by level'!$G$5:$Z$32,MATCH($A31&"|Power",'Stats by level'!$A$5:$A$32,0),20),0))
A33: Basic attack rows show damage per hit. Weak-point hits ×1.5 (Spec 01). Ranks, branch upgrades and passives are in Spec 02.

Sheet Ultimates
A1: Ultimate Forms (Spec 03) — damage at L20 Power
A3: Lineage | B3: Branch | C3: Ultimate | D3: Area / range | E3: Timing | F3: Effect | G3: Damage (text) | H3: Base | I3: Ratio × P | J3: Cooldown (s) | K3: Flagged | L3: Damage @ L20
A4: Titan | B4: Aggression | C4: Colossus Step | D4: Self; each step a quake of radius 4 m | E4: 6 s; a step every 0.7 s | F4: Size ×1.25; −20% damage taken; each step staggers 0.3 s (no CC immunity triggered) | G4: 30 + 0.3 × P per step | H4: 30 | I4: 0.3 | J4: 100 | L4: =IF(I4="","",ROUND(H4+I4*INDEX('Stats by level'!$G$5:$Z$32,MATCH($A4&"|Power",'Stats by level'!$A$5:$A$32,0),20),0)) -> 84
A5: Titan | B5: Aggression | C5: Avalanche | D5: Line, 30 m | E5: 3 s charge, unstoppable | F5: Rolls through everything; knocks enemies aside | G5: 100 + 1.0 × P to creatures; 600 + 3 × P to structures | H5: 100 | I5: 1 | J5: 110 | L5: =IF(I5="","",ROUND(H5+I5*INDEX('Stats by level'!$G$5:$Z$32,MATCH($A5&"|Power",'Stats by level'!$A$5:$A$32,0),20),0)) -> 280
A6: Titan | B6: Aggression | C6: Shatterfist | D6: Melee, 4 m | E6: 0.6 s wind-up | F6: If it hits a weak point, the weak point breaks instantly | G6: 150 + 1.5 × P | H6: 150 | I6: 1.5 | J6: 90 | K6: Yes | L6: =IF(I6="","",ROUND(H6+I6*INDEX('Stats by level'!$G$5:$Z$32,MATCH($A6&"|Power",'Stats by level'!$A$5:$A$32,0),20),0)) -> 420
A7: Titan | B7: Tactical | C7: Fortress | D7: Self + 120° cone behind, 6 m | E7: 6 s; can't move | F7: Titan takes −50% damage; allies behind take −40% | G7: — | J7: 100 | L7: =IF(I7="","",ROUND(H7+I7*INDEX('Stats by level'!$G$5:$Z$32,MATCH($A7&"|Power",'Stats by level'!$A$5:$A$32,0),20),0))
A8: Titan | B8: Tactical | C8: Fault Line | D8: Line, 25 m | E8: 0.8 s to crack; lasts 8 s | F8: Nodes on the Titan's side of the line can't be captured or uprooted by enemies; crossing the crack slows 50% | G8: — | J8: 120 | L8: =IF(I8="","",ROUND(H8+I8*INDEX('Stats by level'!$G$5:$Z$32,MATCH($A8&"|Power",'Stats by level'!$A$5:$A$32,0),20),0))
A9: Titan | B9: Tactical | C9: Mountain's Patience | D9: Self; becomes a platform of radius 6 m, height 6 m | E9: 3 s channel; lasts 10 s | F9: Titan is invulnerable and can't act; allies can climb it for high ground; can end early | G9: — | J9: 130 | L9: =IF(I9="","",ROUND(H9+I9*INDEX('Stats by level'!$G$5:$Z$32,MATCH($A9&"|Power",'Stats by level'!$A$5:$A$32,0),20),0))
A10: Brawler | B10: Aggression | C10: Frenzy | D10: Self | E10: 8 s | F10: +40% attack speed; 20% lifesteal (subject to the healing cap) | G10: — | J10: 90 | L10: =IF(I10="","",ROUND(H10+I10*INDEX('Stats by level'!$G$5:$Z$32,MATCH($A10&"|Power",'Stats by level'!$A$5:$A$32,0),20),0))
A11: Brawler | B11: Aggression | C11: Wrecking Rush | D11: Line, 20 m | E11: 1.5 s charge | F11: Smashes through a structure; knocks enemies back 5 m | G11: 80 + 0.8 × P to creatures; 800 + 3 × P to structures | H11: 80 | I11: 0.8 | J11: 110 | L11: =IF(I11="","",ROUND(H11+I11*INDEX('Stats by level'!$G$5:$Z$32,MATCH($A11&"|Power",'Stats by level'!$A$5:$A$32,0),20),0)) -> 272
A12: Brawler | B12: Aggression | C12: Last Stand | D12: Self | E12: 6 s | F12: Can't drop below 1 Health; at the end, heals 15% max Health if alive | G12: — | J12: 120 | L12: =IF(I12="","",ROUND(H12+I12*INDEX('Stats by level'!$G$5:$Z$32,MATCH($A12&"|Power",'Stats by level'!$A$5:$A$32,0),20),0))
A13: Brawler | B13: Tactical | C13: Pin | D13: Melee, 3 m; any Stage | E13: 3 s | F13: Both the Brawler and the target are stunned; allies deal +20% damage to the pinned target | G13: — | J13: 100 | L13: =IF(I13="","",ROUND(H13+I13*INDEX('Stats by level'!$G$5:$Z$32,MATCH($A13&"|Power",'Stats by level'!$A$5:$A$32,0),20),0))
A14: Brawler | B14: Tactical | C14: Brawl Circle | D14: Ring, radius 10 m around self | E14: 0.5 s to form; lasts 5 s | F14: No one can enter or leave (blocks movement and dashes, not projectiles) | G14: — | J14: 110 | L14: =IF(I14="","",ROUND(H14+I14*INDEX('Stats by level'!$G$5:$Z$32,MATCH($A14&"|Power",'Stats by level'!$A$5:$A$32,0),20),0))
A15: Brawler | B15: Tactical | C15: Shove of the Storm | D15: Cone 90°, 10 m | E15: 0.4 s wind-up | F15: Knockback 15 m; interrupts channels | G15: 60 + 0.6 × P | H15: 60 | I15: 0.6 | J15: 90 | L15: =IF(I15="","",ROUND(H15+I15*INDEX('Stats by level'!$G$5:$Z$32,MATCH($A15&"|Power",'Stats by level'!$A$5:$A$32,0),20),0)) -> 204
A16: Verdant | B16: Aggression | C16: Thornstorm | D16: Aura, radius 5 m | E16: 6 s | F16: Damage every 0.5 s to enemies nearby | G16: 40 + 0.4 × P per second | H16: 40 | I16: 0.4 | J16: 100 | L16: =IF(I16="","",ROUND(H16+I16*INDEX('Stats by level'!$G$5:$Z$32,MATCH($A16&"|Power",'Stats by level'!$A$5:$A$32,0),20),0)) -> 100
A17: Verdant | B17: Aggression | C17: Strangling Grove | D17: Target Hub or Enemy Core within 20 m | E17: 8 s | F17: Trees grow through the structure; enemies near it rooted 0.5 s when it starts | G17: 150 + 1.5 × P per second to the structure | H17: 150 | I17: 1.5 | J17: 120 | L17: =IF(I17="","",ROUND(H17+I17*INDEX('Stats by level'!$G$5:$Z$32,MATCH($A17&"|Power",'Stats by level'!$A$5:$A$32,0),20),0)) -> 375
A18: Verdant | B18: Aggression | C18: Sap Frenzy | D18: Allies within 15 m | E18: 10 s | F18: Spends up to 300 team SAP; allies gain +3% Power per 30 SAP spent (max +30%) | G18: — | J18: 100 | L18: =IF(I18="","",ROUND(H18+I18*INDEX('Stats by level'!$G$5:$Z$32,MATCH($A18&"|Power",'Stats by level'!$A$5:$A$32,0),20),0))
A19: Verdant | B19: Tactical | C19: Overgrowth | D19: Every Vulnerable or neutral node within 15 m | E19: Instant | F19: Captures them all for the Verdant's team | G19: — | J19: 140 | L19: =IF(I19="","",ROUND(H19+I19*INDEX('Stats by level'!$G$5:$Z$32,MATCH($A19&"|Power",'Stats by level'!$A$5:$A$32,0),20),0))
A20: Verdant | B20: Tactical | C20: Living Wall | D20: Wall, 40 m long, placed up to 20 m away | E20: 1.0 s to grow; lasts 15 s | F20: Blocks movement and projectiles; reshapes paths | G20: Wall Health 1,500 + 5 × P per 10 m segment | H20: 1500 | I20: 5 | J20: 120 | L20: =IF(I20="","",ROUND(H20+I20*INDEX('Stats by level'!$G$5:$Z$32,MATCH($A20&"|Power",'Stats by level'!$A$5:$A$32,0),20),0)) -> 2250
A21: Verdant | B21: Tactical | C21: Greenhome | D21: Circle, radius 12 m | E21: 10 s | F21: Allies heal 4% max Health/s (cap applies); enemies slowed 30% | G21: — | J21: 110 | L21: =IF(I21="","",ROUND(H21+I21*INDEX('Stats by level'!$G$5:$Z$32,MATCH($A21&"|Power",'Stats by level'!$A$5:$A$32,0),20),0))
A22: Hollow | B22: Aggression | C22: Collapse | D22: Circle, radius 6 m, up to 20 m away | E22: 1.0 s delay | F22: Pulls enemies toward the centre, then implodes | G22: 200 + 2.0 × P at the centre, falling to 50% at the edge | H22: 200 | I22: 2 | J22: 100 | L22: =IF(I22="","",ROUND(H22+I22*INDEX('Stats by level'!$G$5:$Z$32,MATCH($A22&"|Power",'Stats by level'!$A$5:$A$32,0),20),0)) -> 620
A23: Hollow | B23: Aggression | C23: Hollow Out | D23: Target enemy Hub within 20 m | E23: Instant | F23: Hub Defense Level −3 (minimum 1) for 45 s | G23: — | J23: 120 | L23: =IF(I23="","",ROUND(H23+I23*INDEX('Stats by level'!$G$5:$Z$32,MATCH($A23&"|Power",'Stats by level'!$A$5:$A$32,0),20),0))
A24: Hollow | B24: Aggression | C24: Unmaking | D24: Next 3 basic attacks within 6 s | E24: — | F24: Each hit removes all shields and buffs from the target and deals +50% damage | G24: +50% on 3 basics | J24: 90 | L24: =IF(I24="","",ROUND(H24+I24*INDEX('Stats by level'!$G$5:$Z$32,MATCH($A24&"|Power",'Stats by level'!$A$5:$A$32,0),20),0))
A25: Hollow | B25: Tactical | C25: Event Horizon | D25: Circle, radius 10 m, up to 15 m away | E25: 0.8 s delay | F25: Pulls all enemies to the centre; stagger 0.5 s | G25: 80 + 0.8 × P | H25: 80 | I25: 0.8 | J25: 110 | L25: =IF(I25="","",ROUND(H25+I25*INDEX('Stats by level'!$G$5:$Z$32,MATCH($A25&"|Power",'Stats by level'!$A$5:$A$32,0),20),0)) -> 248
A26: Hollow | B26: Tactical | C26: Silence of the Deep | D26: Circle, radius 15 m around self | E26: 4 s | F26: No one (allies included) can use abilities or Synergies; basic attacks allowed | G26: — | J26: 120 | L26: =IF(I26="","",ROUND(H26+I26*INDEX('Stats by level'!$G$5:$Z$32,MATCH($A26&"|Power",'Stats by level'!$A$5:$A$32,0),20),0))
A27: Hollow | B27: Tactical | C27: Step Between | D27: Allies within 10 m (and self) | E27: 2 s channel | F27: Teleports them all to any node the team holds | G27: — | J27: 150 | K27: Yes | L27: =IF(I27="","",ROUND(H27+I27*INDEX('Stats by level'!$G$5:$Z$32,MATCH($A27&"|Power",'Stats by level'!$A$5:$A$32,0),20),0))
A28: Thornrunner | B28: Aggression | C28: Hunt Frenzy | D28: Self; whole map | E28: 10 s | F28: +30% speed; all enemies carrying 200+ cores revealed; +15% damage to them | G28: — | J28: 100 | L28: =IF(I28="","",ROUND(H28+I28*INDEX('Stats by level'!$G$5:$Z$32,MATCH($A28&"|Power",'Stats by level'!$A$5:$A$32,0),20),0))
A29: Thornrunner | B29: Aggression | C29: Gut the Hoard | D29: Melee, 3 m | E29: 0.3 s | F29: Target drops 50% of its carried cores on the ground | G29: 120 + 1.0 × P | H29: 120 | I29: 1 | J29: 90 | L29: =IF(I29="","",ROUND(H29+I29*INDEX('Stats by level'!$G$5:$Z$32,MATCH($A29&"|Power",'Stats by level'!$A$5:$A$32,0),20),0)) -> 350
A30: Thornrunner | B30: Aggression | C30: Endless Pursuit | D30: Self | E30: 8 s | F30: Takedowns reset all Q/E/R cooldowns | G30: — | J30: 110 | L30: =IF(I30="","",ROUND(H30+I30*INDEX('Stats by level'!$G$5:$Z$32,MATCH($A30&"|Power",'Stats by level'!$A$5:$A$32,0),20),0))
A31: Thornrunner | B31: Tactical | C31: Pack Hunt | D31: Team | E31: 8 s | F31: Resets Mark Prey; while the mark lasts, all allies see its weak point and move +20% toward it | G31: — | J31: 100 | L31: =IF(I31="","",ROUND(H31+I31*INDEX('Stats by level'!$G$5:$Z$32,MATCH($A31&"|Power",'Stats by level'!$A$5:$A$32,0),20),0))
A32: Thornrunner | B32: Tactical | C32: Thicket Trap | D32: 3 snares on nodes within 30 m | E32: Hidden for 60 s | F32: An enemy stepping on a snare is rooted 1.5 s and revealed 5 s | G32: 40 + 0.4 × P | H32: 40 | I32: 0.4 | J32: 110 | L32: =IF(I32="","",ROUND(H32+I32*INDEX('Stats by level'!$G$5:$Z$32,MATCH($A32&"|Power",'Stats by level'!$A$5:$A$32,0),20),0)) -> 132
A33: Thornrunner | B33: Tactical | C33: Scent Trail | D33: Every cell the team holds | E33: 20 s | F33: Every enemy standing on the team's territory is revealed | G33: — | J33: 120 | L33: =IF(I33="","",ROUND(H33+I33*INDEX('Stats by level'!$G$5:$Z$32,MATCH($A33&"|Power",'Stats by level'!$A$5:$A$32,0),20),0))
A34: Bonespire | B34: Aggression | C34: Marrow Barrage | D34: 5 lances, 50 m | E34: Over 3 s | F34: Each can hit a weak point (×1.5, or ×2.0 if exposed) | G34: 70 + 0.9 × P per lance | H34: 70 | I34: 0.9 | J34: 100 | L34: =IF(I34="","",ROUND(H34+I34*INDEX('Stats by level'!$G$5:$Z$32,MATCH($A34&"|Power",'Stats by level'!$A$5:$A$32,0),20),0)) -> 304
A35: Bonespire | B35: Aggression | C35: Siege Spire | D35: Lance, 60 m | E35: 3.0 s wind-up | F35: Huge lance; ×3 damage to structures | G35: 150 + 1.5 × P; (150 + 1.5 × P) × 3 to structures | H35: 150 | I35: 1.5 | J35: 110 | L35: =IF(I35="","",ROUND(H35+I35*INDEX('Stats by level'!$G$5:$Z$32,MATCH($A35&"|Power",'Stats by level'!$A$5:$A$32,0),20),0)) -> 540
A36: Bonespire | B36: Aggression | C36: Rememberer's Aim | D36: Self | E36: 8 s | F36: Every hit counts as a weak-point hit (×1.5) | G36: ×1.5 on all hits | J36: 110 | L36: =IF(I36="","",ROUND(H36+I36*INDEX('Stats by level'!$G$5:$Z$32,MATCH($A36&"|Power",'Stats by level'!$A$5:$A$32,0),20),0))
A37: Bonespire | B37: Tactical | C37: Bone Cathedral | D37: Self; turret range 30 m | E37: 10 s; can't move | F37: Fires at structures (priority) and enemies in range | G37: 100 + 1.0 × P per second to structures; 40 + 0.4 × P per second to creatures | H37: 100 | I37: 1 | J37: 120 | L37: =IF(I37="","",ROUND(H37+I37*INDEX('Stats by level'!$G$5:$Z$32,MATCH($A37&"|Power",'Stats by level'!$A$5:$A$32,0),20),0)) -> 360
A38: Bonespire | B38: Tactical | C38: Ossuary Maze | D38: 6 fences in a 15 m radius | E38: 0.5 s to rise; lasts 10 s | F38: Reshapes an area into a maze | G38: Fence Health as Ossuary | J38: 120 | L38: =IF(I38="","",ROUND(H38+I38*INDEX('Stats by level'!$G$5:$Z$32,MATCH($A38&"|Power",'Stats by level'!$A$5:$A$32,0),20),0))
A39: Bonespire | B39: Tactical | C39: Fossilise | D39: Target enemy within 20 m | E39: 0.4 s | F39: Stun 2 s, not reduced by Tenacity; the target's allies can break the stone early (Health 300 + 2 × P) | G39: — | J39: 110 | L39: =IF(I39="","",ROUND(H39+I39*INDEX('Stats by level'!$G$5:$Z$32,MATCH($A39&"|Power",'Stats by level'!$A$5:$A$32,0),20),0))
A40: Stillheart | B40: Aggression | C40: Killing Frost | D40: Cone 70°, 15 m | E40: 0.5 s wind-up | F40: Freezes enemies (stun 1.5 s); the first hit on a frozen target shatters the ice for bonus damage | G40: 150 + 1.5 × P on shatter | H40: 150 | I40: 1.5 | J40: 100 | L40: =IF(I40="","",ROUND(H40+I40*INDEX('Stats by level'!$G$5:$Z$32,MATCH($A40&"|Power",'Stats by level'!$A$5:$A$32,0),20),0)) -> 375
A41: Stillheart | B41: Aggression | C41: Rime March | D41: Self; ice 4 m around | E41: 8 s | F41: Enemy nodes whose core cell the ice touches become Vulnerable for 15 s | G41: — | J41: 110 | L41: =IF(I41="","",ROUND(H41+I41*INDEX('Stats by level'!$G$5:$Z$32,MATCH($A41&"|Power",'Stats by level'!$A$5:$A$32,0),20),0))
...

Sheet Synergies
A1: Pair Synergies and phase matrix (Spec 02 §9)
A3: Synergy | B3: Pair | C3: Unlock level | D3: Trigger | E3: Effect | F3: Cooldown S1 (s) | G3: Cooldown S2 (s) | H3: Cooldown S3 (s)
A4: Void Garden | B4: Verdant + Hollow | C4: 12 | D4: Void Rift on ground the Verdant rooted, or the Verdant roots inside a Void Rift | E4: Field radius 8 m, 6 s: enemies −50% Control and can't capture; allied nodes inside can't be uprooted; neutral/Vulnerable nodes inside captured 50% faster | F4: 15 | G4: 12 | H4: 9
A5: Co-Stalk | B5: Thornrunner + Bonespire | C5: 15 | D5: Spire Lance within 4 s of Mark Prey on the same target | E5: The Lance homes to the weak point (within 15° of aim); on hit, weak point breaks instantly; target revealed 4 s more | F5: 15 | G5: 12 | H5: 9
A6: Smash & Roll | B6: Titan + Brawler | C6: 18 | D6: Roll Commit begins within 1.5 s of Quake Slam staggering the target | E6: Target Airborne 1.0 s; takes +40% damage from both partners; both gain 30 Momentum (Brawler) / 30% Quake Slam cooldown refund (Titan) | F6: 15 | G6: 12 | H6: 9
A9: Phase matrix — cooldown (s) by phase; "Locked" = unusable
A10: Phase | B10: S1 | C10: S2 | D10: S3
A11: 1 · Stable Flow | B11: =F4 -> 15 | C11: =G4 -> 12 | D11: =H4 -> 9
A12: 2 · Pre-Aggro | B12: =F4 -> 15 | C12: =G4 -> 12 | D12: =H4 -> 9
A13: 3 · Resource Stage | B13: Locked | C13: 31 | D13: 20
A14: 4 · Hunt | B14: Locked | C14: Locked | D14: 9
A16: Lullaby Resonance (Stillheart within 15 m): Synergy cooldowns − | E16: 0.1
A17: Example: Phase 3 S3 cooldown with Lullaby Resonance (s) | E17: =D13*(1-E16) -> 18

Sheet Creatures
A1: Creatures (Spec 04) — Health by phase and affinity cores
A2: Phase multipliers → | C2: P1 | D2: 1 | E2: P2 | F2: 1.15 | G2: P3 | H2: 1.3 | I2: P4 | J2: 1.45 | K2: Affinity | L2: 1.25
A3: # | B3: Creature | C3: Group | D3: Tier | E3: Health (Phase 1) | F3: Hit damage | G3: Speed (m/s) | H3: Group size | I3: Cores (text) | J3: Cores | K3: SAP | L3: Key numbers | M3: Health P2 | N3: Health P3 | O3: Health P4 | P3: Cores with affinity
A4: 1 | B4: Mossback Grazer | C4: Four-legged | D4: II | E4: 900 | F4: — (passive) | G4: 3.5 | H4: Herd of 4 | I4: 45 each | J4: 45 | K4: 0 | L4: Grazing on an enemy cell adds 5% uproot progress/s (about 20 s a cell). Herding: a player within 6 m behind the herd pushes it forward at 3.5 m/s | M4: =IF(ISNUMBER(E4),ROUND(E4*$F$2,0),"—") -> 1035 | N4: =IF(ISNUMBER(E4),ROUND(E4*$H$2,0),"—") -> 1170 | O4: =IF(ISNUMBER(E4),ROUND(E4*$J$2,0),"—") -> 1305 | P4: =ROUND(J4*$L$2,0) -> 56
A5: 2 | B5: Ashfang | C5: Four-legged | D5: II | E5: 700 | F5: 50 / 1.0 s | G5: 7 | H5: Pack of 3 | I5: 50 each | J5: 50 | K5: 0 | L5: Hunts any player below 30% Health within 40 m; +30% damage to them | M5: =IF(ISNUMBER(E5),ROUND(E5*$F$2,0),"—") -> 805 | N5: =IF(ISNUMBER(E5),ROUND(E5*$H$2,0),"—") -> 910 | O5: =IF(ISNUMBER(E5),ROUND(E5*$J$2,0),"—") -> 1015 | P5: =ROUND(J5*$L$2,0) -> 63
A6: 3 | B6: Stonehide Ox | C6: Four-legged | D6: III | E6: 3500 | F6: 140 | G6: 4 | H6: Solo | I6: 160 + 20 SAP | J6: 160 | K6: 20 | L6: Charge: 25 m line at 10 m/s, 200 damage, knockdown (stun 1.0 s) to everything hit, creatures included; cooldown 10 s | M6: =IF(ISNUMBER(E6),ROUND(E6*$F$2,0),"—") -> 4025 | N6: =IF(ISNUMBER(E6),ROUND(E6*$H$2,0),"—") -> 4550 | O6: =IF(ISNUMBER(E6),ROUND(E6*$J$2,0),"—") -> 5075 | P6: =ROUND(J6*$L$2,0) -> 200
A7: 4 | B7: Glimmerfox | C7: Four-legged | D7: I | E7: 150 | F7: — | G7: 8 | H7: Solo | I7: 20 | J7: 20 | K7: 0 | L7: Invisible after 2 s still. Killing it reveals enemies within 15 m for 6 s (Thornrunner: 25 m) | M7: =IF(ISNUMBER(E7),ROUND(E7*$F$2,0),"—") -> 173 | N7: =IF(ISNUMBER(E7),ROUND(E7*$H$2,0),"—") -> 195 | O7: =IF(ISNUMBER(E7),ROUND(E7*$J$2,0),"—") -> 218 | P7: =ROUND(J7*$L$2,0) -> 25
